Traceback (most recent call last):
  File "/Users/tliu/Github/comsc341-cd/venv/lib/python3.11/site-packages/jupyter_cache/executors/utils.py", line 58, in single_nb_execution
    executenb(
  File "/Users/tliu/Github/comsc341-cd/venv/lib/python3.11/site-packages/nbclient/client.py", line 1319, in execute
    return NotebookClient(nb=nb, resources=resources, km=km, **kwargs).execute()
           ^^^^^^^^^^^^^^^^^^^^^^^^^^^^^^^^^^^^^^^^^^^^^^^^^^^^^^^^^^^^^^^^^^^^^
  File "/Users/tliu/Github/comsc341-cd/venv/lib/python3.11/site-packages/jupyter_core/utils/__init__.py", line 165, in wrapped
    return loop.run_until_complete(inner)
           ^^^^^^^^^^^^^^^^^^^^^^^^^^^^^^
  File "/Users/tliu/.pyenv/versions/3.11.10/lib/python3.11/asyncio/base_events.py", line 654, in run_until_complete
    return future.result()
           ^^^^^^^^^^^^^^^
  File "/Users/tliu/Github/comsc341-cd/venv/lib/python3.11/site-packages/nbclient/client.py", line 709, in async_execute
    await self.async_execute_cell(
  File "/Users/tliu/Github/comsc341-cd/venv/lib/python3.11/site-packages/nbclient/client.py", line 1062, in async_execute_cell
    await self._check_raise_for_error(cell, cell_index, exec_reply)
  File "/Users/tliu/Github/comsc341-cd/venv/lib/python3.11/site-packages/nbclient/client.py", line 918, in _check_raise_for_error
    raise CellExecutionError.from_cell_and_msg(cell, exec_reply_content)
nbclient.exceptions.CellExecutionError: An error occurred while executing the following cell:
------------------
#### test fit_propensity_score ####
if __name__ == "__main__":
    test_df = pd.DataFrame({'X': [0, 6, 5], 'T': [0, 0, 1]})
    test_preds = fit_propensity_score(test_df, 'T', ['X'])
    assert test_preds.shape[0] == test_df.shape[0], "The predictions should have the same number of elements as the input dataframe"

    # these tests are not exhaustive, so adding additional asserts and test cases is recommended
    print("All asserts for fit_propensity_score passed!")
------------------


[0;31m---------------------------------------------------------------------------[0m
[0;31mAttributeError[0m                            Traceback (most recent call last)
Cell [0;32mIn[3], line 5[0m
[1;32m      3[0m test_df [38;5;241m=[39m pd[38;5;241m.[39mDataFrame({[38;5;124m'[39m[38;5;124mX[39m[38;5;124m'[39m: [[38;5;241m0[39m, [38;5;241m6[39m, [38;5;241m5[39m], [38;5;124m'[39m[38;5;124mT[39m[38;5;124m'[39m: [[38;5;241m0[39m, [38;5;241m0[39m, [38;5;241m1[39m]})
[1;32m      4[0m test_preds [38;5;241m=[39m fit_propensity_score(test_df, [38;5;124m'[39m[38;5;124mT[39m[38;5;124m'[39m, [[38;5;124m'[39m[38;5;124mX[39m[38;5;124m'[39m])
[0;32m----> 5[0m [38;5;28;01massert[39;00m [43mtest_preds[49m[38;5;241;43m.[39;49m[43mshape[49m[[38;5;241m0[39m] [38;5;241m==[39m test_df[38;5;241m.[39mshape[[38;5;241m0[39m], [38;5;124m"[39m[38;5;124mThe predictions should have the same number of elements as the input dataframe[39m[38;5;124m"[39m
[1;32m      7[0m [38;5;66;03m# these tests are not exhaustive, so adding additional asserts and test cases is recommended[39;00m
[1;32m      8[0m [38;5;28mprint[39m([38;5;124m"[39m[38;5;124mAll asserts for fit_propensity_score passed![39m[38;5;124m"[39m)

[0;31mAttributeError[0m: 'NoneType' object has no attribute 'shape'

