Traceback (most recent call last):
  File "/Users/tliu/Github/comsc341-cd/venv/lib/python3.11/site-packages/jupyter_cache/executors/utils.py", line 58, in single_nb_execution
    executenb(
  File "/Users/tliu/Github/comsc341-cd/venv/lib/python3.11/site-packages/nbclient/client.py", line 1319, in execute
    return NotebookClient(nb=nb, resources=resources, km=km, **kwargs).execute()
           ^^^^^^^^^^^^^^^^^^^^^^^^^^^^^^^^^^^^^^^^^^^^^^^^^^^^^^^^^^^^^^^^^^^^^
  File "/Users/tliu/Github/comsc341-cd/venv/lib/python3.11/site-packages/jupyter_core/utils/__init__.py", line 165, in wrapped
    return loop.run_until_complete(inner)
           ^^^^^^^^^^^^^^^^^^^^^^^^^^^^^^
  File "/Users/tliu/.pyenv/versions/3.11.10/lib/python3.11/asyncio/base_events.py", line 654, in run_until_complete
    return future.result()
           ^^^^^^^^^^^^^^^
  File "/Users/tliu/Github/comsc341-cd/venv/lib/python3.11/site-packages/nbclient/client.py", line 709, in async_execute
    await self.async_execute_cell(
  File "/Users/tliu/Github/comsc341-cd/venv/lib/python3.11/site-packages/nbclient/client.py", line 1062, in async_execute_cell
    await self._check_raise_for_error(cell, cell_index, exec_reply)
  File "/Users/tliu/Github/comsc341-cd/venv/lib/python3.11/site-packages/nbclient/client.py", line 918, in _check_raise_for_error
    raise CellExecutionError.from_cell_and_msg(cell, exec_reply_content)
nbclient.exceptions.CellExecutionError: An error occurred while executing the following cell:
------------------
# selects all the South Hadley datapoints
display(traffic_df.loc["South Hadley"])

------------------


[0;31m---------------------------------------------------------------------------[0m
[0;31mKeyError[0m                                  Traceback (most recent call last)
Cell [0;32mIn[3], line 2[0m
[1;32m      1[0m [38;5;66;03m# selects all the South Hadley datapoints[39;00m
[0;32m----> 2[0m display([43mtraffic_df[49m[38;5;241;43m.[39;49m[43mloc[49m[43m[[49m[38;5;124;43m"[39;49m[38;5;124;43mSouth Hadley[39;49m[38;5;124;43m"[39;49m[43m][49m)

File [0;32m~/Github/comsc341-cd/venv/lib/python3.11/site-packages/pandas/core/indexing.py:1191[0m, in [0;36m_LocationIndexer.__getitem__[0;34m(self, key)[0m
[1;32m   1189[0m maybe_callable [38;5;241m=[39m com[38;5;241m.[39mapply_if_callable(key, [38;5;28mself[39m[38;5;241m.[39mobj)
[1;32m   1190[0m maybe_callable [38;5;241m=[39m [38;5;28mself[39m[38;5;241m.[39m_check_deprecated_callable_usage(key, maybe_callable)
[0;32m-> 1191[0m [38;5;28;01mreturn[39;00m [38;5;28;43mself[39;49m[38;5;241;43m.[39;49m[43m_getitem_axis[49m[43m([49m[43mmaybe_callable[49m[43m,[49m[43m [49m[43maxis[49m[38;5;241;43m=[39;49m[43maxis[49m[43m)[49m

File [0;32m~/Github/comsc341-cd/venv/lib/python3.11/site-packages/pandas/core/indexing.py:1431[0m, in [0;36m_LocIndexer._getitem_axis[0;34m(self, key, axis)[0m
[1;32m   1429[0m [38;5;66;03m# fall thru to straight lookup[39;00m
[1;32m   1430[0m [38;5;28mself[39m[38;5;241m.[39m_validate_key(key, axis)
[0;32m-> 1431[0m [38;5;28;01mreturn[39;00m [38;5;28;43mself[39;49m[38;5;241;43m.[39;49m[43m_get_label[49m[43m([49m[43mkey[49m[43m,[49m[43m [49m[43maxis[49m[38;5;241;43m=[39;49m[43maxis[49m[43m)[49m

File [0;32m~/Github/comsc341-cd/venv/lib/python3.11/site-packages/pandas/core/indexing.py:1381[0m, in [0;36m_LocIndexer._get_label[0;34m(self, label, axis)[0m
[1;32m   1379[0m [38;5;28;01mdef[39;00m [38;5;21m_get_label[39m([38;5;28mself[39m, label, axis: AxisInt):
[1;32m   1380[0m     [38;5;66;03m# GH#5567 this will fail if the label is not present in the axis.[39;00m
[0;32m-> 1381[0m     [38;5;28;01mreturn[39;00m [38;5;28;43mself[39;49m[38;5;241;43m.[39;49m[43mobj[49m[38;5;241;43m.[39;49m[43mxs[49m[43m([49m[43mlabel[49m[43m,[49m[43m [49m[43maxis[49m[38;5;241;43m=[39;49m[43maxis[49m[43m)[49m

File [0;32m~/Github/comsc341-cd/venv/lib/python3.11/site-packages/pandas/core/generic.py:4301[0m, in [0;36mNDFrame.xs[0;34m(self, key, axis, level, drop_level)[0m
[1;32m   4299[0m             new_index [38;5;241m=[39m index[loc]
[1;32m   4300[0m [38;5;28;01melse[39;00m:
[0;32m-> 4301[0m     loc [38;5;241m=[39m [43mindex[49m[38;5;241;43m.[39;49m[43mget_loc[49m[43m([49m[43mkey[49m[43m)[49m
[1;32m   4303[0m     [38;5;28;01mif[39;00m [38;5;28misinstance[39m(loc, np[38;5;241m.[39mndarray):
[1;32m   4304[0m         [38;5;28;01mif[39;00m loc[38;5;241m.[39mdtype [38;5;241m==[39m np[38;5;241m.[39mbool_:

File [0;32m~/Github/comsc341-cd/venv/lib/python3.11/site-packages/pandas/core/indexes/range.py:417[0m, in [0;36mRangeIndex.get_loc[0;34m(self, key)[0m
[1;32m    415[0m         [38;5;28;01mraise[39;00m [38;5;167;01mKeyError[39;00m(key) [38;5;28;01mfrom[39;00m [38;5;21;01merr[39;00m
[1;32m    416[0m [38;5;28;01mif[39;00m [38;5;28misinstance[39m(key, Hashable):
[0;32m--> 417[0m     [38;5;28;01mraise[39;00m [38;5;167;01mKeyError[39;00m(key)
[1;32m    418[0m [38;5;28mself[39m[38;5;241m.[39m_check_indexing_error(key)
[1;32m    419[0m [38;5;28;01mraise[39;00m [38;5;167;01mKeyError[39;00m(key)

[0;31mKeyError[0m: 'South Hadley'

