Traceback (most recent call last):
  File "/Users/tliu/Github/comsc341-cd/venv/lib/python3.11/site-packages/jupyter_cache/executors/utils.py", line 58, in single_nb_execution
    executenb(
  File "/Users/tliu/Github/comsc341-cd/venv/lib/python3.11/site-packages/nbclient/client.py", line 1319, in execute
    return NotebookClient(nb=nb, resources=resources, km=km, **kwargs).execute()
           ^^^^^^^^^^^^^^^^^^^^^^^^^^^^^^^^^^^^^^^^^^^^^^^^^^^^^^^^^^^^^^^^^^^^^
  File "/Users/tliu/Github/comsc341-cd/venv/lib/python3.11/site-packages/jupyter_core/utils/__init__.py", line 165, in wrapped
    return loop.run_until_complete(inner)
           ^^^^^^^^^^^^^^^^^^^^^^^^^^^^^^
  File "/Users/tliu/.pyenv/versions/3.11.10/lib/python3.11/asyncio/base_events.py", line 654, in run_until_complete
    return future.result()
           ^^^^^^^^^^^^^^^
  File "/Users/tliu/Github/comsc341-cd/venv/lib/python3.11/site-packages/nbclient/client.py", line 709, in async_execute
    await self.async_execute_cell(
  File "/Users/tliu/Github/comsc341-cd/venv/lib/python3.11/site-packages/nbclient/client.py", line 1062, in async_execute_cell
    await self._check_raise_for_error(cell, cell_index, exec_reply)
  File "/Users/tliu/Github/comsc341-cd/venv/lib/python3.11/site-packages/nbclient/client.py", line 918, in _check_raise_for_error
    raise CellExecutionError.from_cell_and_msg(cell, exec_reply_content)
nbclient.exceptions.CellExecutionError: An error occurred while executing the following cell:
------------------
# Group by the intervention column and the two covariates
all_cols = ['intervention', 'success_expect', 'frst_in_family']
#group_count = learning_df.groupby(all_cols, as_index=False).ngroups


print(f"Number actual groups among the bins for {all_cols}: {group_count}")
------------------


[0;31m---------------------------------------------------------------------------[0m
[0;31mNameError[0m                                 Traceback (most recent call last)
Cell [0;32mIn[6], line 6[0m
[1;32m      2[0m all_cols [38;5;241m=[39m [[38;5;124m'[39m[38;5;124mintervention[39m[38;5;124m'[39m, [38;5;124m'[39m[38;5;124msuccess_expect[39m[38;5;124m'[39m, [38;5;124m'[39m[38;5;124mfrst_in_family[39m[38;5;124m'[39m]
[1;32m      3[0m [38;5;66;03m#group_count = learning_df.groupby(all_cols, as_index=False).ngroups[39;00m
[0;32m----> 6[0m [38;5;28mprint[39m([38;5;124mf[39m[38;5;124m"[39m[38;5;124mNumber actual groups among the bins for [39m[38;5;132;01m{[39;00mall_cols[38;5;132;01m}[39;00m[38;5;124m: [39m[38;5;132;01m{[39;00m[43mgroup_count[49m[38;5;132;01m}[39;00m[38;5;124m"[39m)

[0;31mNameError[0m: name 'group_count' is not defined

