Traceback (most recent call last):
  File "/Users/tliu/Github/comsc341-cd/venv/lib/python3.11/site-packages/jupyter_cache/executors/utils.py", line 58, in single_nb_execution
    executenb(
  File "/Users/tliu/Github/comsc341-cd/venv/lib/python3.11/site-packages/nbclient/client.py", line 1319, in execute
    return NotebookClient(nb=nb, resources=resources, km=km, **kwargs).execute()
           ^^^^^^^^^^^^^^^^^^^^^^^^^^^^^^^^^^^^^^^^^^^^^^^^^^^^^^^^^^^^^^^^^^^^^
  File "/Users/tliu/Github/comsc341-cd/venv/lib/python3.11/site-packages/jupyter_core/utils/__init__.py", line 165, in wrapped
    return loop.run_until_complete(inner)
           ^^^^^^^^^^^^^^^^^^^^^^^^^^^^^^
  File "/Users/tliu/.pyenv/versions/3.11.10/lib/python3.11/asyncio/base_events.py", line 654, in run_until_complete
    return future.result()
           ^^^^^^^^^^^^^^^
  File "/Users/tliu/Github/comsc341-cd/venv/lib/python3.11/site-packages/nbclient/client.py", line 709, in async_execute
    await self.async_execute_cell(
  File "/Users/tliu/Github/comsc341-cd/venv/lib/python3.11/site-packages/nbclient/client.py", line 1062, in async_execute_cell
    await self._check_raise_for_error(cell, cell_index, exec_reply)
  File "/Users/tliu/Github/comsc341-cd/venv/lib/python3.11/site-packages/nbclient/client.py", line 918, in _check_raise_for_error
    raise CellExecutionError.from_cell_and_msg(cell, exec_reply_content)
nbclient.exceptions.CellExecutionError: An error occurred while executing the following cell:
------------------
vote_df['age'].mean()

# approach 1
vote_df.loc[T=1]['age'].mean()
vote_df.loc[T=0]['age'].mean()

# approach 2
vote_df.groupby('treatment')['age']
------------------


[0;36m  Cell [0;32mIn[13], line 4[0;36m[0m
[0;31m    vote_df.loc[T=1]['age'].mean()[0m
[0m                ^[0m
[0;31mSyntaxError[0m[0;31m:[0m invalid syntax. Maybe you meant '==' or ':=' instead of '='?


